Workbook

Sheet README
A1: AI Infrastructure Sizing and BOM Workbook - README
A3: README companion file not found.

Sheet Input
A1: Executive and Technical Inputs
A3: Input ID | B3: Input | C3: Value | D3: Unit | E3: Input Type | F3: Why Required | G3: Validation / Status | H3: Downstream Decision | I3: Value Status | J3: Production Replacement
A4: IN-001 | B4: Workload Type | C4: RAG / Inference | D4: mode | E4: Dropdown | F4: Selects the calculation and catalog branch | G4: Required | H4: Workload Rule ID | I4: User Provided | J4: N/A
A5: IN-002 | B5: Query Complexity | C5: Simple | D5: profile | E5: Dropdown | F5: Drives query tokens and model quality tier | G5: Required | H5: Workload Rule / model | I5: User Provided | J5: N/A
A6: IN-003 | B6: Response Detail | C6: Detailed | D6: profile | E6: Dropdown | F6: Drives output tokens and quality requirement | G6: Required | H6: Model / decode demand | I6: User Provided | J6: N/A
A7: IN-004 | B7: Conversation Length | C7: Medium | D7: profile | E7: Dropdown | F7: Drives retained turns and context | G7: Required | H7: Context / KV cache | I7: User Provided | J7: N/A
A8: IN-005 | B8: Retrieval Depth | C8: High | D8: profile | E8: Dropdown | F8: Drives retrieved chunks for RAG workloads | G8: Conditional | H8: Context / vector search | I8: User Provided | J8: N/A
A9: IN-006 | B9: Agentic Complexity | C9: Basic | D9: profile | E9: Dropdown | F9: Drives capability tier and model-call planning | G9: Required | H9: Model capability / call rate | I9: User Provided | J9: N/A
A10: IN-007 | B10: Tool Calls per Request | C10: 5 | D10: calls/request | E10: Whole number | F10: Drives tool capability and tool-result context | G10: >=0 | H10: Workload Rule / network | I10: User Provided | J10: N/A
A11: IN-008 | B11: Required Language Coverage | C11: English only | D11: profile | E11: Dropdown | F11: Filters model language eligibility | G11: Required | H11: Model selection | I11: User Provided | J11: N/A
A12: IN-009 | B12: Knowledge Base Size | C12: 10 | D12: TB | E12: Numeric | F12: Drives vector, storage and embedding towers | G12: >=0 | H12: RAG infrastructure | I12: User Provided | J12: N/A
A13: IN-010 | B13: Peak Concurrent Sessions | C13: 1000 | D13: sessions | E13: Whole number | F13: Drives concurrency and KV-cache demand | G13: >0 | H13: GPU capacity | I13: User Provided | J13: N/A
A14: IN-011 | B14: Peak Requests per Second | C14: 5 | D14: requests/sec | E14: Numeric | F14: Drives throughput demand | G14: >0 | H14: GPU capacity | I14: User Provided | J14: N/A
A15: IN-012 | B15: Required P95 TTFT | C15: 1000 | D15: ms | E15: Numeric | F15: Filters benchmark configurations | G15: >0 | H15: GPU benchmark | I15: User Provided | J15: N/A
A16: IN-013 | B16: Required Generation Speed (Default) | C16: 20 | D16: tokens/sec/session | E16: Numeric | F16: Filters decode benchmark configurations | G16: >0 | H16: GPU benchmark | I16: User Provided | J16: N/A
A17: IN-014 | B17: Precision Preference | C17: Auto | D17: precision | E17: Dropdown | F17: Selects model weight memory and mapping | G17: Required | H17: Model-GPU mapping | I17: User Provided | J17: N/A
A18: IN-015 | B18: Availability Requirement | C18: HA | D18: policy | E18: Dropdown | F18: Determines production redundancy | G18: Required | H18: Server quantity | I18: User Provided | J18: N/A
A19: IN-016 | B19: Additional HA Servers | C19: 1 | D19: servers | E19: Whole number | F19: Explicit HA capacity rule | G19: >=0 | H19: Server quantity | I19: User Provided | J19: N/A
A20: IN-017 | B20: DR Requirement | C20: Warm DR | D20: policy | E20: Dropdown | F20: Determines DR capacity requirement | G20: Required | H20: DR quantity | I20: User Provided | J20: N/A
A21: IN-018 | B21: DR Compute Capacity | C21: 0.5 | D21: % of production | E21: Percentage | F21: Explicit DR compute ratio | G21: 0-100% | H21: DR quantity | I21: User Provided | J21: N/A
A22: IN-019 | B22: Planning Period | C22: 3 | D22: years | E22: Whole number | F22: Sets future capacity horizon | G22: >=1 | H22: Growth quantity | I22: User Provided | J22: N/A
A23: IN-020 | B23: Annual Workload Growth | C23: 0.2 | D23: % | E23: Percentage | F23: Drives future compute demand | G23: >=0 | H23: Growth quantity | I23: User Provided | J23: N/A
A24: IN-021 | B24: Annual Data Growth | C24: 0.2 | D24: % | E24: Percentage | F24: Drives future storage demand | G24: >=0 | H24: Storage quantity | I24: User Provided | J24: N/A
A25: IN-022 | B25: System Prompt Tokens | C25: 600 | D25: tokens/call | E25: Governed planning input | F25: Required for context calculation | G25: Planning - replace with tokenizer measurement | H25: Context window | I25: Planning | J25: Selected-model tokenizer
A26: IN-023 | B26: Formatting Overhead per Turn | C26: 20 | D26: tokens/turn | E26: Governed planning input | F26: Required for history tokens | G26: Planning - replace with tokenizer measurement | H26: Context window | I26: Planning | J26: Prompt-template measurement
A27: IN-024 | B27: Average Retrieved Chunk Tokens | C27: 512 | D27: tokens/chunk | E27: Governed planning input | F27: Required for retrieved context | G27: Planning - replace with tokenizer measurement | H27: Context window | I27: Planning | J27: Selected-model tokenizer
A28: IN-025 | B28: Average Tool Result Tokens | C28: 150 | D28: tokens/tool call | E28: Governed planning input | F28: Required for tool context | G28: Planning - replace with payload measurement | H28: Context window | I28: Planning | J28: Tool payload measurement
A29: IN-026 | B29: Model Override | D29: Model ID | E29: Optional | F29: Allows governed manual selection | G29: Override reason required | H29: Model selection | I29: User Provided | J29: N/A
A30: IN-027 | B30: Override Reason | D30: text | E30: Text | F30: Documents any manual override | G30: Conditional | H30: Auditability | I30: User Provided | J30: N/A
A31: IN-028 | B31: Validated Model Calls per Request | C31: 2 | D31: calls/request | E31: Whole number | F31: Converts business requests into actual model-serving demand | G31: Planning - replace with workflow trace | H31: RPS, prefill and decode capacity | I31: Planning | J31: Workflow execution trace

Sheet Model_Mapping_Catalog
A1: Model and Workload Mapping Catalog
A2: AI Model Master
A3: Model ID | B3: Model Family | C3: Model Name / Version | D3: Parameters B | E3: Architecture | F3: Context Window Tokens | G3: Supported Languages | H3: RAG Fit | I3: Tool Calling | J3: Structured Output | K3: On-Prem Eligible | L3: Weights Available | M3: Licence | N3: Commercial Use | O3: Serving Frameworks | P3: Model Source URL | Q3: Source Status | R3: Quality Evidence Status | S3: Catalog Status | T3: Review Note | AE3: Domain Quality | AF3: Language Test | AG3: Groundedness | AH3: Tool Reliability | AI3: JSON Reliability | AJ3: Context Test | AK3: Production Model Status
A4: MOD-001 | B4: Llama | C4: Llama 3.1 8B Instruct | D4: 8 | E4: Dense decoder | F4: 131072 | G4: English, German, French, Italian, Portuguese, Hindi, Spanish, Thai | H4: High | I4: Yes | J4: Yes | K4: Yes | L4: Yes | M4: Llama 3.1 Community License | N4: Review required | O4: NVIDIA NIM; vLLM; TensorRT-LLM | P4: https://github.com/meta-llama/llama-models/blob/main/models/llama3_1/MODEL_CARD.md | Q4: Source-backed | R4: Banking evaluation required | S4: Active | T4: Candidate, not automatic final selection | AE4: Planning Threshold Met | AF4: Planning Threshold Met | AG4: Planning Threshold Met | AH4: Planning Threshold Met | AI4: Planning Threshold Met | AJ4: Planning Threshold Met | AK4: Candidate Model
A5: MOD-002 | B5: Llama | C5: Llama 3.1 70B Instruct | D5: 70 | E5: Dense decoder | F5: 131072 | G5: English, German, French, Italian, Portuguese, Hindi, Spanish, Thai | H5: High | I5: Yes | J5: Yes | K5: Yes | L5: Yes | M5: Llama 3.1 Community License | N5: Review required | O5: NVIDIA NIM; vLLM; TensorRT-LLM | P5: https://github.com/meta-llama/llama-models/blob/main/models/llama3_1/MODEL_CARD.md | Q5: Source-backed | R5: Banking evaluation required | S5: Active | T5: Large model; benchmark and precision required | AE5: Planning Threshold Met | AF5: Planning Threshold Met | AG5: Planning Threshold Met | AH5: Planning Threshold Met | AI5: Planning Threshold Met | AJ5: Planning Threshold Met | AK5: Candidate Model
A6: MOD-003 | B6: Llama | C6: Llama 3.3 70B Instruct | D6: 70 | E6: Dense decoder | F6: 131072 | G6: English, German, French, Italian, Portuguese, Hindi, Spanish, Thai | H6: High | I6: Yes | J6: Yes | K6: Yes | L6: Yes | M6: Llama 3.3 Community License | N6: Review required | O6: NVIDIA NIM; vLLM; TensorRT-LLM | P6: https://github.com/meta-llama/llama-models/blob/main/models/llama3_3/MODEL_CARD.md | Q6: Source-backed | R6: Banking evaluation required | S6: Active | T6: Published NVIDIA NIM profiles available | AE6: Planning Threshold Met | AF6: Planning Threshold Met | AG6: Planning Threshold Met | AH6: Planning Threshold Met | AI6: Planning Threshold Met | AJ6: Planning Threshold Met | AK6: Candidate Model
A7: MOD-004 | B7: Qwen | C7: Qwen2.5 7B Instruct | D7: 7 | E7: Dense decoder | F7: 32768 | G7: Multilingual; validate required language | H7: High | I7: Yes | J7: Yes | K7: Yes | L7: Yes | M7: Apache-2.0 | N7: Yes | O7: vLLM; SGLang; Transformers | P7: https://huggingface.co/collections/Qwen/qwen25 | Q7: Source-backed | R7: Banking evaluation required | S7: Active | T7: Check deployed context profile | AE7: Planning Threshold Met | AF7: Planning Threshold Met | AG7: Planning Threshold Met | AH7: Planning Threshold Met | AI7: Planning Threshold Met | AJ7: Planning Threshold Met | AK7: Candidate Model
A8: MOD-005 | B8: Qwen | C8: Qwen2.5 14B Instruct | D8: 14 | E8: Dense decoder | F8: 32768 | G8: Multilingual; validate required language | H8: High | I8: Yes | J8: Yes | K8: Yes | L8: Yes | M8: Apache-2.0 | N8: Yes | O8: vLLM; SGLang; Transformers | P8: https://huggingface.co/Qwen/Qwen2.5-14B-Instruct | Q8: Source-backed | R8: Banking evaluation required | S8: Active | T8: Good middle candidate subject to evaluation | AE8: Planning Threshold Met | AF8: Planning Threshold Met | AG8: Planning Threshold Met | AH8: Planning Threshold Met | AI8: Planning Threshold Met | AJ8: Planning Threshold Met | AK8: Candidate Model
A9: MOD-006 | B9: Qwen | C9: Qwen2.5 32B Instruct | D9: 32 | E9: Dense decoder | F9: 32768 | G9: Multilingual; validate required language | H9: High | I9: Yes | J9: Yes | K9: Yes | L9: Yes | M9: Apache-2.0 | N9: Yes | O9: vLLM; SGLang; Transformers | P9: https://huggingface.co/collections/Qwen/qwen25 | Q9: Source-backed | R9: Banking evaluation required | S9: Active | T9: Advanced candidate; benchmark required | AE9: Planning Threshold Met | AF9: Planning Threshold Met | AG9: Planning Threshold Met | AH9: Planning Threshold Met | AI9: Planning Threshold Met | AJ9: Planning Threshold Met | AK9: Candidate Model
A10: MOD-007 | B10: Qwen | C10: Qwen2.5 72B Instruct | D10: 72 | E10: Dense decoder | F10: 32768 | G10: Multilingual; validate required language | H10: High | I10: Yes | J10: Yes | K10: Yes | L10: Yes | M10: Qwen licence | N10: Review required | O10: vLLM; SGLang; Transformers | P10: https://huggingface.co/collections/Qwen/qwen25 | Q10: Source-backed | R10: Banking evaluation required | S10: Review | T10: Licence and benchmark review | AE10: Planning Threshold Met | AF10: Planning Threshold Met | AG10: Planning Threshold Met | AH10: Planning Threshold Met | AI10: Planning Threshold Met | AJ10: Planning Threshold Met | AK10: Candidate Model
A11: MOD-008 | B11: Mistral | C11: Mistral Small 3 24B Instruct | D11: 24 | E11: Dense decoder | F11: 32768 | G11: Multilingual; see model card | H11: High | I11: Yes | J11: Yes | K11: Yes | L11: Yes | M11: Apache-2.0 | N11: Yes | O11: vLLM; Mistral inference | P11: https://huggingface.co/mistralai/Mistral-Small-24B-Instruct-2501 | Q11: Source-backed | R11: Banking evaluation required | S11: Active | T11: 32K context | AE11: Planning Threshold Met | AF11: Planning Threshold Met | AG11: Planning Threshold Met | AH11: Planning Threshold Met | AI11: Planning Threshold Met | AJ11: Planning Threshold Met | AK11: Candidate Model
A12: MOD-009 | B12: Mistral | C12: Mistral Small 3.1 24B Instruct | D12: 24 | E12: Dense multimodal | F12: 131072 | G12: 24 languages including English, Hindi, Bengali, Arabic and Chinese | H12: High | I12: Yes | J12: Yes | K12: Yes | L12: Yes | M12: Apache-2.0 | N12: Yes | O12: vLLM; Mistral inference | P12: https://huggingface.co/mistralai/Mistral-Small-3.1-24B-Instruct-2503 | Q12: Source-backed | R12: Banking evaluation required | S12: Active | T12: Long-context multilingual candidate | AE12: Planning Threshold Met | AF12: Planning Threshold Met | AG12: Planning Threshold Met | AH12: Planning Threshold Met | AI12: Planning Threshold Met | AJ12: Planning Threshold Met | AK12: Candidate Model
A13: MOD-010 | B13: Embedding | C13: NV-Embed-e5-v5 | D13: Data Required | E13: Embedding encoder | F13: Model specific | G13: Multilingual; verify model card | H13: Embedding only | I13: No | J13: Vector output | K13: Yes | L13: Yes | M13: Model terms review | N13: Review required | O13: NVIDIA NIM | P13: https://docs.omniverse.nvidia.com/services/latest/services/usd-code/support-matrix.html | Q13: Source-backed | R13: Retrieval evaluation required | S13: Active | T13: Use for embedding tower, not text generation | AE13: Planning Threshold Met | AF13: Planning Threshold Met | AG13: Planning Threshold Met | AH13: N/A | AI13: N/A | AJ13: Planning Threshold Met | AK13: Candidate Model
A16: Workload Rule Catalog
A17: Workload Rule ID | B17: Workload / Use Case | C17: Query Complexity | D17: Response Detail | E17: Required Context Tier | F17: Agentic Complexity | G17: Tool Calls / Request | H17: Language Tier | I17: Minimum Capability Requirement | J17: Preferred Model Size Class | K17: Model Selection Rule | L17: Knowledge Base Role | M17: GPU Workload Class | N17: Production Evidence Required | O17: Status | P17: Notes
A18: WRK-001 | B18: Embedding generation | C18: Simple | D18: Vector output | E18: Model-specific | F18: None | G18: 0 | H18: Any evaluated | I18: Embedding encoder | J18: Embedding model | K18: Select embedding model by language, dimension, quality and throughput | L18: Drives vector count and embedding volume | M18: Embedding / efficient inference | N18: Embedding throughput benchmark | O18: Active | P18: Does not select generation LLM
A19: WRK-002 | B19: RAG chatbot - light | C19: Simple | D19: Short / Detailed | E19: CTX1 <= 8K | F19: None / Basic | G19: 0-1 | H19: English or evaluated language | I19: RAG + optional basic tools | J19: 7B-14B candidate | K19: Choose smallest model passing quality, context and language tests | L19: Drives vector DB and storage, not direct LLM size | M19: Efficient inference | N19: Banking quality + matched GPU benchmark | O19: Active | P19: Typical L4/L40S candidate after benchmark
A20: WRK-003 | B20: RAG chatbot - medium | C20: Medium | D20: Detailed | E20: CTX2 <= 32K | F20: Basic / Moderate | G20: 1-4 | H20: English or evaluated multilingual | I20: RAG + tools + structured output | J20: 14B-32B candidate | K20: Compare 14B, 24B and 32B candidates by banking evaluation | L20: Separate RAG infrastructure sizing | M20: Generative AI inference | N20: Banking quality + matched GPU benchmark | O20: Active | P20: Often L40S/H100/H200 candidate depending SLA
A21: WRK-004 | B21: RAG chatbot - advanced | C21: Complex | D21: Analytical | E21: CTX3 <= 64K | F21: Moderate / Advanced | G21: 2-5 | H21: Evaluated multilingual | I21: Advanced reasoning + tools | J21: 24B-70B candidate | K21: Select model only after quality and long-context evaluation | L21: Separate RAG infrastructure sizing | M21: High-intensity inference | N21: Banking quality + exact workload benchmark | O21: Active | P21: Multi-GPU may be required
A22: WRK-005 | B22: Long-context document assistant | C22: Medium / Complex | D22: Detailed / Analytical | E22: CTX4 <= 128K | F22: Basic / Moderate | G22: 0-4 | H22: Evaluated multilingual | I22: Long context + RAG | J22: 24B-70B long-context candidate | K22: Filter context first, then quality and benchmark | L22: Large KB remains storage driver | M22: Memory-heavy inference | N22: Long-context quality + KV cache benchmark | O22: Active | P22: H200/MI300X type capacity may help
A23: WRK-006 | B23: Agentic banking assistant | C23: Complex | D23: Detailed / Analytical | E23: CTX2-CTX4 | F23: Advanced | G23: 5+ | H23: Evaluated multilingual | I23: Reliable tool calling + JSON + reasoning | J23: 24B-70B candidate | K23: Require tool-call and workflow evaluation | L23: Tool payloads increase context, not KB size | M23: High-intensity inference | N23: Workflow trace + matched concurrency benchmark | O23: Active | P23: Model calls and tool calls separate
A24: WRK-007 | B24: Batch summarization | C24: Medium | D24: Report | E24: CTX2-CTX4 | F24: None | G24: 0 | H24: Evaluated language | I24: Long output + batch throughput | J24: 14B-70B candidate | K24: Rank by quality and offline throughput | L24: Input dataset affects batch storage | M24: Batch inference | N24: Offline throughput benchmark | O24: Active | P24: Latency may be relaxed
A25: WRK-008 | B25: LoRA / QLoRA fine-tuning | C25: Model dependent | D25: Model dependent | E25: Sequence length dependent | F25: N/A | G25: 0 | H25: Model dependent | I25: PEFT support | J25: Selected base model | K25: GPU selection uses weights, gradients/optimizer/activations and method | L25: Dataset size drives training storage | M25: Fine-tuning | N25: Training memory and completion-time benchmark | O25: Active | P25: Inference mapping cannot size fine-tuning
A26: WRK-009 | B26: Full fine-tuning | C26: Model dependent | D26: Model dependent | E26: Sequence length dependent | F26: N/A | G26: 0 | H26: Model dependent | I26: Distributed training | J26: Selected base model | K26: Use separate training calculation and distributed strategy | L26: Dataset/checkpoint storage | M26: Training | N26: Distributed training benchmark | O26: Active | P26: High-memory multi-GPU fabric required
A27: WRK-010 | B27: Foundation model training | C27: Target architecture | D27: N/A | E27: Training sequence length | F27: N/A | G27: 0 | H27: Training corpus | I27: Distributed pretraining | J27: Custom target | K27: Do not use inference sizing logic | L27: Corpus and checkpoint storage dominate | M27: Large-scale training | N27: End-to-end training plan and benchmark | O27: Active | P27: Separate project branch
A28: WRK-011 | B28: Multimodal assistant | C28: Medium / Complex | D28: Detailed / Analytical | E28: CTX2-CTX4 | F28: Basic / Moderate | G28: 0-4 | H28: Evaluated language | I28: Vision + text + structured output | J28: Multimodal model | K28: Filter multimodal capability, context, language and on-prem eligibility | L28: Image/data storage branch | M28: Multimodal inference | N28: Vision quality and GPU benchmark | O28: Active | P28: Not applicable to predictive ML
A29: Model-to-GPU Mapping Catalog
A30: Mapping ID | B30: Workload Rule ID | C30: Model ID | D30: Model Name | E30: Workload Type | F30: Precision | G30: Bytes / Parameter | H30: Model Weight Memory GB | I30: Runtime + KV Memory GB | J30: Total Required VRAM GB | K30: GPU ID | L30: GPU Vendor | M30: GPU SKU | N30: GPU VRAM GB | O30: Weights-Only Minimum GPUs | P30: Production Minimum GPUs | Q30: Dell Compatibility ID | R30: Dell Server Pair | S30: Dell Pairing Status | T30: Framework / Profile | U30: Tensor Parallelism | V30: Context / Concurrency Condition | W30: Mapping Evidence | X30: Benchmark Status | Y30: Fit Status | Z30: Mapping Source URL | AA30: Review Note | AB30: Catalog Status | AC30: Selection Key | AD30: Priority | AE30: Benchmark ID | AF30: Benchmark Match Type | AG30: Benchmark Confidence | AH30: Production Mapping Status
A31: MGPU-001 | B31: WRK-002 | C31: MOD-001 | D31: Llama 3.1 8B Instruct | E31: RAG Inference | F31: BF16 | G31: 2 | H31: 16 | I31: Data Required | J31: Data Required | K31: GPU-NV-001 | L31: NVIDIA | M31: L4 | N31: 24 | O31: 1 | P31: Data Required | Q31: CMP-010 | R31: PowerEdge XE7745 | S31: Confirmed example | T31: NVIDIA NIM / generic profile | U31: 1 | V31: Must match measured input/output tokens, concurrency and SLA | W31: NIM memory guideline and Dell GPU compatibility | X31: Benchmark Required | Y31: Conditional | Z31: https://docs.nvidia.com/nim/large-language-models/latest/reference/support-matrix.html | AA31: Benchmark required for RPS/TTFT | AB31: Active | AC31: =C31&"|"&B31 -> MOD-001|WRK-002 | AD31: =IF(S31="Confirmed",1,IF(S31="Confirmed example",2,3)) -> 2 | AE31: BM-PROXY-L4 | AF31: Nearest Planning Proxy | AG31: Low | AH31: Planning
A32: MGPU-002 | B32: WRK-002 | C32: MOD-001 | D32: Llama 3.1 8B Instruct | E32: RAG Inference | F32: BF16 | G32: 2 | H32: 16 | I32: Data Required | J32: Data Required | K32: GPU-NV-002 | L32: NVIDIA | M32: L40S | N32: 48 | O32: 1 | P32: Data Required | Q32: CMP-001 | R32: PowerEdge R760xa | S32: Confirmed | T32: NVIDIA NIM optimized/generic | U32: 1 | V32: Must match measured input/output tokens, concurrency and SLA | W32: NIM supports Llama 8B profiles; Dell supports L40S | X32: Benchmark Required | Y32: Conditional | Z32: https://docs.nvidia.com/nim/large-language-models/latest/reference/support-matrix.html | AA32: Preferred candidate only after matched benchmark | AB32: Active | AC32: =C32&"|"&B32 -> MOD-001|WRK-002 | AD32: =IF(S32="Confirmed",1,IF(S32="Confirmed example",2,3)) -> 1 | AE32: BM-PROXY-L40S | AF32: Nearest Planning Proxy | AG32: Low | AH32: Planning
A33: MGPU-003 | B33: WRK-002 | C33: MOD-004 | D33: Qwen2.5 7B Instruct | E33: RAG Inference | F33: BF16 | G33: 2 | H33: 14 | I33: Data Required | J33: Data Required | K33: GPU-NV-002 | L33: NVIDIA | M33: L40S | N33: 48 | O33: 1 | P33: Data Required | Q33: CMP-001 | R33: PowerEdge R760xa | S33: Confirmed | T33: vLLM / SGLang | U33: 1 | V33: Must match measured input/output tokens, concurrency and SLA | W33: Model-card framework support plus memory fit | X33: Benchmark Required | Y33: Conditional | Z33: https://huggingface.co/collections/Qwen/qwen25 | AA33: Performance benchmark required | AB33: Active | AC33: =C33&"|"&B33 -> MOD-004|WRK-002 | AD33: =IF(S33="Confirmed",1,IF(S33="Confirmed example",2,3)) -> 1 | AE33: BM-PROXY-L40S | AF33: Nearest Planning Proxy | AG33: Low | AH33: Planning
A34: MGPU-004 | B34: WRK-003 | C34: MOD-005 | D34: Qwen2.5 14B Instruct | E34: RAG Inference | F34: BF16 | G34: 2 | H34: 28 | I34: Data Required | J34: Data Required | K34: GPU-NV-002 | L34: NVIDIA | M34: L40S | N34: 48 | O34: 1 | P34: Data Required | Q34: CMP-001 | R34: PowerEdge R760xa | S34: Confirmed | T34: vLLM / SGLang | U34: 1 | V34: Must match measured input/output tokens, concurrency and SLA | W34: Model-card framework support plus memory fit | X34: Benchmark Required | Y34: Conditional | Z34: https://huggingface.co/Qwen/Qwen2.5-14B-Instruct | AA34: KV cache and concurrency may increase GPU count | AB34: Active | AC34: =C34&"|"&B34 -> MOD-005|WRK-003 | AD34: =IF(S34="Confirmed",1,IF(S34="Confirmed example",2,3)) -> 1 | AE34: BM-PROXY-L40S | AF34: Nearest Planning Proxy | AG34: Low | AH34: Planning
A35: MGPU-005 | B35: WRK-003 | C35: MOD-008 | D35: Mistral Small 3 24B | E35: RAG Inference | F35: INT8 | G35: 1 | H35: 24 | I35: Data Required | J35: Data Required | K35: GPU-NV-002 | L35: NVIDIA | M35: L40S | N35: 48 | O35: 1 | P35: Data Required | Q35: CMP-001 | R35: PowerEdge R760xa | S35: Confirmed | T35: vLLM | U35: 1 | V35: Must match measured input/output tokens, concurrency and SLA | W35: Model fits weights-only; quantization quality validation required | X35: Benchmark Required | Y35: Conditional | Z35: https://huggingface.co/mistralai/Mistral-Small-24B-Instruct-2501 | AA35: Production benchmark required | AB35: Active | AC35: =C35&"|"&B35 -> MOD-008|WRK-003 | AD35: =IF(S35="Confirmed",1,IF(S35="Confirmed example",2,3)) -> 1 | AE35: BM-PROXY-L40S | AF35: Nearest Planning Proxy | AG35: Low | AH35: Planning
A36: MGPU-006 | B36: WRK-005 | C36: MOD-009 | D36: Mistral Small 3.1 24B | E36: Long-context RAG Inference | F36: INT8 | G36: 1 | H36: 24 | I36: Data Required | J36: Data Required | K36: GPU-NV-002 | L36: NVIDIA | M36: L40S | N36: 48 | O36: 1 | P36: Data Required | Q36: CMP-001 | R36: PowerEdge R760xa | S36: Confirmed | T36: vLLM | U36: 1 | V36: Must match measured input/output tokens, concurrency and SLA | W36: Weights-only candidate; 128K KV cache can dominate | X36: Benchmark Required | Y36: Conditional | Z36: https://huggingface.co/mistralai/Mistral-Small-3.1-24B-Instruct-2503 | AA36: Long-context benchmark required | AB36: Active | AC36: =C36&"|"&B36 -> MOD-009|WRK-005 | AD36: =IF(S36="Confirmed",1,IF(S36="Confirmed example",2,3)) -> 1 | AE36: BM-PROXY-L40S | AF36: Nearest Planning Proxy | AG36: Low | AH36: Planning
A37: MGPU-007 | B37: WRK-003 | C37: MOD-006 | D37: Qwen2.5 32B Instruct | E37: RAG Inference | F37: INT8 | G37: 1 | H37: 32 | I37: Data Required | J37: Data Required | K37: GPU-NV-003 | L37: NVIDIA | M37: H100 PCIe 80GB | N37: 80 | O37: 1 | P37: Data Required | Q37: CMP-002 | R37: PowerEdge R760xa | S37: Confirmed | T37: vLLM / SGLang | U37: 1 | V37: Must match measured input/output tokens, concurrency and SLA | W37: Weights-only fit; framework and quality source | X37: Benchmark Required | Y37: Conditional | Z37: https://huggingface.co/collections/Qwen/qwen25 | AA37: Production benchmark required | AB37: Active | AC37: =C37&"|"&B37 -> MOD-006|WRK-003 | AD37: =IF(S37="Confirmed",1,IF(S37="Confirmed example",2,3)) -> 1 | AE37: Benchmark Required | AF37: Benchmark Required | AG37: Low | AH37: Planning
A38: MGPU-008 | B38: WRK-004 | C38: MOD-002 | D38: Llama 3.1 70B Instruct | E38: RAG Inference | F38: FP8 | G38: 1 | H38: 70 | I38: Data Required | J38: Data Required | K38: GPU-NV-003 | L38: NVIDIA | M38: H100 PCIe 80GB | N38: 80 | O38: 1 | P38: Data Required | Q38: CMP-002 | R38: PowerEdge R760xa | S38: Confirmed | T38: NVIDIA NIM FP8 profile | U38: 1 | V38: Must match measured input/output tokens, concurrency and SLA | W38: NIM has FP8 TP profiles; memory headroom must be validated | X38: Benchmark Required | Y38: Conditional | Z38: https://docs.nvidia.com/nim/large-language-models/latest/reference/support-matrix.html | AA38: Production likely needs topology based on KV/cache and SLA | AB38: Active | AC38: =C38&"|"&B38 -> MOD-002|WRK-004 | AD38: =IF(S38="Confirmed",1,IF(S38="Confirmed example",2,3)) -> 1 | AE38: Benchmark Required | AF38: Benchmark Required | AG38: Low | AH38: Planning
A39: MGPU-009 | B39: WRK-004 | C39: MOD-003 | D39: Llama 3.3 70B Instruct | E39: RAG Inference | F39: FP8 | G39: 1 | H39: 70 | I39: Data Required | J39: Data Required | K39: GPU-NV-004 | L39: NVIDIA | M39: H100 SXM5 80GB | N39: 80 | O39: 1 | P39: Data Required | Q39: CMP-003 | R39: PowerEdge XE8640 | S39: Confirmed | T39: NVIDIA NIM FP8 TP2/TP4 | U39: 2 | V39: Must match measured input/output tokens, concurrency and SLA | W39: NIM provides supported FP8 TP profiles; Dell fixed H100 platform | X39: Benchmark Required | Y39: Conditional | Z39: https://docs.nvidia.com/nim/large-language-models/latest/reference/support-matrix.html | AA39: Use matched token-shape benchmark | AB39: Active | AC39: =C39&"|"&B39 -> MOD-003|WRK-004 | AD39: =IF(S39="Confirmed",1,IF(S39="Confirmed example",2,3)) -> 1 | AE39: BM-H100-5K500-C50 | AF39: Exact Published | AG39: High | AH39: Production Candidate
A40: MGPU-010 | B40: WRK-005 | C40: MOD-003 | D40: Llama 3.3 70B Instruct | E40: Long-context RAG Inference | F40: FP8 | G40: 1 | H40: 70 | I40: Data Required | J40: Data Required | K40: GPU-NV-006 | L40: NVIDIA | M40: H200 SXM5 141GB | N40: 141 | O40: 1 | P40: Data Required | Q40: CMP-005 | R40: PowerEdge XE9680 | S40: Confirmed | T40: NVIDIA NIM FP8 | U40: 2 | V40: Must match measured input/output tokens, concurrency and SLA | W40: NIM/H200 support and Dell pairing | X40: Benchmark Required | Y40: Conditional | Z40: https://docs.nvidia.com/nim/large-language-models/latest/reference/support-matrix.html | AA40: XE9680 is fixed 8-GPU; quantity comes from complete server config | AB40: Active | AC40: =C40&"|"&B40 -> MOD-003|WRK-005 | AD40: =IF(S40="Confirmed",1,IF(S40="Confirmed example",2,3)) -> 1 | AE40: BM-PROXY-H200 | AF40: Nearest Planning Proxy | AG40: Low | AH40: Planning
A41: MGPU-011 | B41: WRK-004 | C41: MOD-003 | D41: Llama 3.3 70B Instruct | E41: RAG Inference | F41: BF16 | G41: 2 | H41: 140 | I41: Data Required | J41: Data Required | K41: GPU-NV-006 | L41: NVIDIA | M41: H200 SXM5 141GB | N41: 141 | O41: 1 | P41: Data Required | Q41: CMP-005 | R41: PowerEdge XE9680 | S41: Confirmed | T41: NVIDIA NIM BF16 TP2+ | U41: 2 | V41: Must match measured input/output tokens, concurrency and SLA | W41: NIM BF16 TP profiles; weight memory approximately 140 GB before runtime | X41: Benchmark Required | Y41: Conditional | Z41: https://docs.nvidia.com/nim/large-language-models/latest/reference/support-matrix.html | AA41: Runtime/KV prevents relying on one-GPU arithmetic | AB41: Active | AC41: =C41&"|"&B41 -> MOD-003|WRK-004 | AD41: =IF(S41="Confirmed",1,IF(S41="Confirmed example",2,3)) -> 1 | AE41: BM-PROXY-H200 | AF41: Nearest Planning Proxy | AG41: Low | AH41: Planning
A42: MGPU-012 | B42: WRK-004 | C42: MOD-003 | D42: Llama 3.3 70B Instruct | E42: RAG Inference | F42: INT4 | G42: 0.5 | H42: 35 | I42: Data Required | J42: Data Required | K42: GPU-AMD-002 | L42: AMD | M42: Instinct MI300X | N42: 192 | O42: 1 | P42: Data Required | Q42: CMP-006 | R42: PowerEdge XE9680 | S42: Confirmed | T42: ROCm / llama.cpp / vLLM | U42: 1 | V42: Must match measured input/output tokens, concurrency and SLA | W42: AMD reports 70B+ model capability; exact configuration benchmark required | X42: Benchmark Required | Y42: Conditional | Z42: https://rocm.blogs.amd.com/ecosystems-and-partners/llama-cpp-oct2025/README.html | AA42: Quantization quality and ROCm serving benchmark required | AB42: Active | AC42: =C42&"|"&B42 -> MOD-003|WRK-004 | AD42: =IF(S42="Confirmed",1,IF(S42="Confirmed example",2,3)) -> 1 | AE42: Benchmark Required | AF42: Benchmark Required | AG42: Low | AH42: Planning
...

Sheet Model_Selection
A1: Input to Workload and Model Selection
A3: Formula ID | B3: Derived Requirement | C3: Value | D3: Unit | E3: Formula / Rule | F3: Value Status | G3: Production Replacement | H3: Decision Impact | I3: Notes
A4: TOK-001 | B4: Query Tokens | C4: =IF(Input!C5="Simple",60,IF(Input!C5="Medium",200,600)) -> 60 | D4: tokens/call | E4: Governed planning map | F4: Planning | G4: Selected-model tokenizer P95 | H4: Context / prefill | I4: Not a universal constant
A5: TOK-002 | B5: Output Tokens | C5: =IF(Input!C6="Short",200,IF(Input!C6="Detailed",600,IF(Input!C6="Analytical",1500,5000))) -> 600 | D5: tokens/call | E5: Governed planning map | F5: Planning | G5: Measured P95 output | H5: Context / decode
A6: TOK-003 | B6: Retained Turns | C6: =IF(Input!C7="Single",0,IF(Input!C7="Short",2,IF(Input!C7="Medium",5,10))) -> 5 | D6: turns | E6: Governed planning map | F6: Planning | G6: Session traces | H6: History / KV cache
A7: RAG-001 | B7: Retrieved Chunks | C7: =IF(ISNUMBER(SEARCH("RAG",Input!C4)),IF(Input!C8="Low",2,IF(Input!C8="Medium",4,8)),0) -> 8 | D7: chunks/call | E7: RAG-only planning map | F7: Planning | G7: RAG evaluation | H7: Retrieved context | I7: Non-RAG returns zero
A8: TOK-004 | B8: Conversation History Tokens | C8: =C6*(C4+C5+Input!C26) -> 3400 | D8: tokens/call | E8: Turns x completed-turn token components | F8: Calculated | G8: Tokenizer/session trace | H8: Context / KV cache
A9: RAG-002 | B9: Retrieved Context Tokens | C9: =C7*Input!C27 -> 4096 | D9: tokens/call | E9: Chunks x chunk tokens | F9: Calculated | G9: Tokenizer measurement | H9: Context / prefill
A10: AGT-001 | B10: Tool Result Tokens | C10: =Input!C10*Input!C28 -> 750 | D10: tokens/request | E10: Tool calls x result tokens | F10: Calculated | G10: Payload trace | H10: Context / network
A11: TOK-005 | B11: Input Tokens per Model Call | C11: =Input!C25+C4+C8+C9+C10 -> 8906 | D11: tokens/call | E11: System + query + history + retrieval + tools | F11: Calculated | G11: Measured P95 trace | H11: Benchmark token shape
A12: TOK-006 | B12: Required Context Window | C12: =C11+C5 -> 9506 | D12: tokens | E12: Input tokens + output allowance | F12: Calculated | G12: Measured P95 trace | H12: Model eligibility
A13: DEM-001 | B13: Model Calls per Second | C13: =Input!C14*Input!C31 -> 10 | D13: calls/sec | E13: Business RPS x validated model calls/request | F13: Calculated | G13: Workflow trace | H13: Throughput
A14: DEM-002 | B14: Required Input Tokens per Second | C14: =C13*C11 -> 89060 | D14: tokens/sec | E14: Model calls/sec x input tokens/call | F14: Calculated | G14: Measured workload | H14: Prefill GPUs
A15: DEM-003 | B15: Required Output Tokens per Second | C15: =C13*C5 -> 6000 | D15: tokens/sec | E15: Model calls/sec x output tokens/call | F15: Calculated | G15: Measured workload | H15: Decode GPUs
A16: DEM-004 | B16: Peak Active Sequences | C16: =Input!C13 -> 1000 | D16: sequences | E16: Peak concurrent sessions | F16: User Provided | G16: Load test | H16: Concurrency GPUs
A17: MOD-001 | B17: Context Tier | C17: =IF(C12<=8192,"CTX1",IF(C12<=32768,"CTX2",IF(C12<=65536,"CTX3",IF(C12<=131072,"CTX4","Above 128K")))) -> CTX2 | D17: tier | E17: Non-overlapping context bands | F17: Calculated | G17: N/A | H17: Workload Rule
A18: MOD-002 | B18: Workload Rule ID | C18: =IF(Input!C4="Embedding Generation","WRK-001",IF(Input!C4="LoRA / QLoRA Fine-Tuning","WRK-008",IF(Input!C4="Full Fine-Tuning","WRK-009",IF(Input!C4="Foundation Model Training","WRK-010",IF(Input!C4="Computer Vision / Multimodal","WRK-011",IF(OR(Input!C4="Predictive ML",Input!C4="Forecasting"),"WRK-012",IF(Input!C4="Batch Inference","WRK-007",IF(OR(Input!C9="Advanced",Input!C10>=5),"WRK-006",IF(C17="CTX4","WRK-005",IF(OR(Input!C5="Complex",Input!C6="Analytical"),"WRK-004",IF(OR(Input!C5="Medium",Input!C6="Detailed",Input!C10>=2),"WRK-003","WRK-002"))))))))))) -> WRK-006 | D18: ID | E18: Workload, context, complexity and tools | F18: Calculated | G18: Catalog extension when needed | H18: Candidate model | I18: Not limited to RAG
A19: MOD-003 | B19: Candidate Model ID | C19: =IF(C18="WRK-001","MOD-010",IF(C18="WRK-002","MOD-004",IF(C18="WRK-003","MOD-005",IF(C18="WRK-004","MOD-003",IF(C18="WRK-005","MOD-009",IF(C18="WRK-006","MOD-003",IF(C18="WRK-007","MOD-008",IF(C18="WRK-008","MOD-005",IF(C18="WRK-009","MOD-003",IF(C18="WRK-010","CUSTOM",IF(C18="WRK-011","MOD-009",IF(C18="WRK-012","NON-LLM","Data Required")))))))))))) -> MOD-003 | D19: Model ID | E19: Deterministic candidate shortlist | F19: Candidate | G19: Governed evaluation evidence | H19: Model selection | I19: Candidate, not approved
A20: MOD-004 | B20: Selected Model ID | C20: =IF(Input!C29<>"",Input!C29,C19) -> MOD-003 | D20: Model ID | E20: Override or candidate | F20: Calculated | G20: Override reason | H20: GPU mapping | I20: Override does not bypass checks
A21: MOD-005 | B21: Selected Model Name | C21: =IFERROR(INDEX(Model_Mapping_Catalog!$C$4:$C$13,MATCH(C20,Model_Mapping_Catalog!$A$4:$A$13,0)),C20) -> Llama 3.3 70B Instruct | D21: text | E21: Model catalog lookup | F21: Calculated | G21: N/A | H21: Output
A22: MOD-006 | B22: Model Context Window | C22: =IFERROR(INDEX(Model_Mapping_Catalog!$F$4:$F$13,MATCH(C20,Model_Mapping_Catalog!$A$4:$A$13,0)),"Data Required") -> 131072 | D22: tokens | E22: Model catalog lookup | F22: Source-Backed | G22: Model card | H22: Eligibility
A23: MOD-007 | B23: Context Eligibility | C23: =IF(OR(C22="Data Required",C12=""),"Data Required",IF(C22>=C12,"Pass","Fail")) -> Pass | D23: status | E23: Model context >= required context | F23: Calculated | G23: Measured context | H23: Hard filter
A24: MOD-008 | B24: Model Evaluation Status | C24: =IF(OR(C20="CUSTOM",C20="NON-LLM"),"Separate Evaluation Branch",IF(C23="Fail","Ineligible","Evaluation Required")) -> Evaluation Required | D24: status | E24: Domain/language/groundedness/tools/JSON/context/licence | F24: Calculated | G24: Load evaluation evidence | H24: Production approval
A25: MOD-009 | B25: Model Selection Status | C25: =IF(C23="Fail","Ineligible",IF(C24="Evaluation Required","Candidate Model","Separate Branch")) -> Candidate Model | D25: status | E25: Combined eligibility status | F25: Calculated | G25: Evaluation evidence | H25: Final label

Sheet Hardware_Mapping_Catalog
A1: Dell Hardware Mapping Catalog
A2: Dell Server Master
A3: Server ID | B3: Dell Server | C3: Generation | D3: Architecture | E3: CPU Platform | F3: CPU Sockets | G3: Max CPU Cores / Socket | H3: Max System RAM TB | I3: Rack Units | J3: Cooling | K3: GPU Form Factor | L3: Max GPU Qty | M3: Max GPU Power | N3: Max Local Storage TB | O3: Network / Expansion Summary | P3: Power Supply Summary | Q3: Primary AI Use | R3: Source URL | S3: Source Status | T3: Price Status | U3: Budgetary Unit Price | V3: Currency
A4: DELL-SRV-001 | B4: PowerEdge R760xa | C4: 16G | D4: x86 | E4: Intel Xeon Scalable 4th/5th Gen | F4: 2 | G4: 64 | H4: 8 | I4: 2 | J4: Air | K4: PCIe: up to 4 DW or up to 12 SW | L4: 4 | M4: Up to 400W class | N4: 122.88 | O4: OCP 3.0 plus PCIe Gen5 expansion; exact NIC by configured BOM | P4: Up to dual 2800W Titanium | Q4: Inference, fine-tuning, VDI | R4: https://www.dell.com/en-us/shop/ipovw/poweredge-r760xa | S4: Source-backed | T4: Quote Required | U4: Data Required | V4: USD
A5: DELL-SRV-002 | B5: PowerEdge XE8640 | C5: 16G | D5: x86 | E5: Intel Xeon Scalable 4th Gen | F5: 2 | G5: 56 | H5: Data Required | I5: 4 | J5: Liquid-cooled GPU tray / air-cooled CPU | K5: SXM | L5: 4 | M5: H100 SXM class | N5: Data Required | O5: High-speed GPU fabric; exact NIC by configured BOM | P5: Data Required | Q5: Dense H100 AI training/inference | R5: https://infohub.delltechnologies.com/en-us/l/design-guide-generative-ai-in-the-enterprise-inferencing/dell-poweredge-servers-and-nvidia-gpus-3/ | S5: Source-backed | T5: Quote Required | U5: Data Required | V5: USD
A6: DELL-SRV-003 | B6: PowerEdge XE9680 | C6: 16G | D6: x86 | E6: Intel Xeon Scalable 4th/5th Gen | F6: 2 | G6: 64 | H6: 4 | I6: 6 | J6: Air / configured accelerator cooling | K6: SXM5 / OAM | L6: 8 | M6: 700-900W accelerator class | N6: 122.88 | O6: Up to 10 front-facing PCIe Gen5 slots; network options by accelerator configuration | P6: Configured high-density redundant power | Q6: Large-model training and inference | R6: https://www.dell.com/en-us/shop/ipovw/poweredge-xe9680 | S6: Source-backed | T6: Quote Required | U6: Data Required | V6: USD
A7: DELL-SRV-004 | B7: PowerEdge XE7745 | C7: 17G | D7: x86 | E7: AMD EPYC 9005 | F7: 2 | G7: 192 | H7: 3.072 | I7: 4 | J7: Air | K7: PCIe Gen5: 8 DW or 16 SW | L7: 8 | M7: Up to 600W DW; 75W SW | N7: 122.88 | O7: 8 additional front-serviceable PCIe slots plus OCP 3.0 | P7: 8 redundant AC/DC power supplies | Q7: Flexible inference and fine-tuning | R7: https://www.dell.com/en-us/shop/ipovw/poweredge-xe7745 | S7: Source-backed | T7: Quote Required | U7: Data Required | V7: USD
A8: DELL-SRV-005 | B8: PowerEdge XE7740 | C8: 17G | D8: x86 | E8: Intel Xeon 6 | F8: 2 | G8: 86 | H8: Data Required | I8: 4 | J8: Air | K8: PCIe accelerator platform | L8: 8 | M8: Configuration dependent | N8: Data Required | O8: PCIe slot cabling per technical manual | P8: 8 redundant AC/DC power supplies | Q8: Flexible AI acceleration | R8: https://www.dell.com/support/product-details/en-us/product/poweredge-xe7740/resources/manuals | S8: Partial - exact GPU list requires matrix revision check | T8: Quote Required | U8: Data Required | V8: USD
A9: DELL-SRV-006 | B9: PowerEdge XE9780 | C9: 17G | D9: x86 | E9: Intel Xeon Scalable 6th Gen | F9: 2 | G9: 86 | H9: 4 | I9: 10 | J9: Air | K9: SXM6 HGX | L9: 8 | M9: 1000-1100W GPU class | N9: 153.6 | O9: B300: 8 embedded CX8 OSFP; B200: up to 12 PCIe Gen5 x16 cards | P9: 12 x 3200W Titanium | Q9: B200/B300 model training and inference | R9: https://www.dell.com/en-us/shop/ipovw/poweredge-xe9780 | S9: Source-backed | T9: Quote Required | U9: Data Required | V9: USD
A10: DELL-SRV-007 | B10: PowerEdge XE9785 | C10: 17G | D10: x86 | E10: AMD EPYC 9005 | F10: 2 | G10: 192 | H10: 6 | I10: 10 | J10: Air | K10: OAM / SXM6 HGX | L10: 8 | M10: 1100-1400W accelerator class | N10: 245.76 | O10: B300: 8 embedded CX8 OSFP; MI355X networking configured separately | P10: 12 x 3200W Titanium | Q10: MI355X/B300 training and inference | R10: https://www.dell.com/en-us/shop/ipovw/poweredge-xe9785 | S10: Source-backed | T10: Quote Required | U10: Data Required | V10: USD
A13: Dell Server-GPU Compatibility Matrix
A14: Compatibility ID | B14: Server ID | C14: Dell Server | D14: GPU Vendor | E14: GPU SKU | F14: GPU Form Factor | G14: Supported Qty / Server | H14: Quantity Rule | I14: GPU VRAM GB / GPU | J14: Total GPU VRAM GB | K14: Interconnect | L14: Maximum GPU TDP W | M14: Workload Fit | N14: Exact Pairing Status | O14: Dell Evidence Type | P14: Dell Source URL | Q14: Source Date / Revision | R14: Configuration Caveat | S14: Selection Priority | T14: Minimum Option | U14: Moderate Option | V14: Heavy Option | W14: Min GPU Qty | X14: Moderate GPU Qty | Y14: Heavy GPU Qty | Z14: Budgetary Base Chassis USD | AA14: Budgetary GPU Unit USD | AB14: Budgetary Config Price USD | AC14: Price Confidence | AD14: Server Height in U's
A15: CMP-001 | B15: DELL-SRV-001 | C15: PowerEdge R760xa | D15: NVIDIA | E15: L40S | F15: PCIe DW | G15: 4 | H15: Up to 4; Dell configuration validation required for 1/2/4 | I15: 48 | J15: 192 | K15: PCIe Gen5; no NVLink | L15: 350 | M15: Generative AI inference | N15: Confirmed | O15: Dell design guide | P15: https://infohub.delltechnologies.com/en-us/l/design-guide-generative-ai-in-the-enterprise-inferencing/dell-poweredge-servers-and-nvidia-gpus-3/ | Q15: Current web design guide | R15: Intermediate quantities must be validated in configurator | S15: High | T15: 1 x L40S | U15: 4 x L40S | V15: Move to H100/H200 platform if SLA unmet | W15: 1 | X15: 4 | Y15: 4 | Z15: 35000 | AA15: 9000 | AB15: =Z15+G15*AA15 -> 71000 | AC15: Medium
A16: CMP-002 | B16: DELL-SRV-001 | C16: PowerEdge R760xa | D16: NVIDIA | E16: H100 PCIe 80GB | F16: PCIe DW | G16: 4 | H16: Up to 4; NVLink bridges pair adjacent GPUs | I16: 80 | J16: 320 | K16: PCIe Gen5; NVLink bridge pair supported | L16: 350 | M16: High-intensity inference / fine-tuning | N16: Confirmed | O16: Dell design guide | P16: https://infohub.delltechnologies.com/en-us/l/design-guide-generative-ai-in-the-enterprise-inferencing/dell-poweredge-servers-and-nvidia-gpus-3/ | Q16: Current web design guide | R16: Exact bridge topology depends on GPU count | S16: High | T16: 1 x H100 PCIe | U16: 2 x H100 PCIe | V16: 4 x H100 PCIe | W16: 1 | X16: 2 | Y16: 4 | Z16: 35000 | AA16: 30000 | AB16: =Z16+G16*AA16 -> 155000 | AC16: Medium
A17: CMP-003 | B17: DELL-SRV-002 | C17: PowerEdge XE8640 | D17: NVIDIA | E17: H100 SXM5 80GB | F17: SXM5 | G17: 4 | H17: Fixed 4-GPU platform | I17: 80 | J17: 320 | K17: NVLink / NVSwitch | L17: 700 | M17: Dense H100 training and inference | N17: Confirmed | O17: Dell design guide | P17: https://infohub.delltechnologies.com/en-us/l/design-guide-generative-ai-in-the-enterprise-inferencing/dell-poweredge-servers-and-nvidia-gpus-3/ | Q17: Current web design guide | R17: Treat as complete 4-GPU configuration | S17: High | T17: Not applicable | U17: 4 x H100 SXM | V17: Scale by server count | W17: 4 | X17: 4 | Y17: 4 | Z17: 60000 | AA17: 30000 | AB17: =Z17+G17*AA17 -> 180000 | AC17: Low
A18: CMP-004 | B18: DELL-SRV-003 | C18: PowerEdge XE9680 | D18: NVIDIA | E18: H100 SXM5 80GB | F18: SXM5 | G18: 8 | H18: Fixed 8-GPU HGX platform | I18: 80 | J18: 640 | K18: NVLink | L18: 700 | M18: Large-model training and inference | N18: Confirmed | O18: Dell product specifications | P18: https://www.dell.com/en-us/shop/ipovw/poweredge-xe9680 | Q18: Current product page | R18: Complete accelerator configuration | S18: High | T18: Not applicable | U18: Not applicable | V18: 8 x H100 SXM | W18: 8 | X18: 8 | Y18: 8 | Z18: 90000 | AA18: 30000 | AB18: =Z18+G18*AA18 -> 330000 | AC18: Low
A19: CMP-005 | B19: DELL-SRV-003 | C19: PowerEdge XE9680 | D19: NVIDIA | E19: H200 SXM5 141GB | F19: SXM5 | G19: 8 | H19: Fixed 8-GPU HGX platform | I19: 141 | J19: 1128 | K19: NVLink | L19: 700 | M19: Memory-intensive large-model inference/training | N19: Confirmed | O19: Dell product specifications | P19: https://www.dell.com/en-us/shop/ipovw/poweredge-xe9680 | Q19: Current product page | R19: Complete accelerator configuration | S19: High | T19: Not applicable | U19: Not applicable | V19: 8 x H200 SXM | W19: 8 | X19: 8 | Y19: 8 | Z19: 90000 | AA19: 40000 | AB19: =Z19+G19*AA19 -> 410000 | AC19: Low
A20: CMP-006 | B20: DELL-SRV-003 | C20: PowerEdge XE9680 | D20: AMD | E20: Instinct MI300X 192GB | F20: OAM | G20: 8 | H20: Fixed 8-accelerator platform | I20: 192 | J20: 1536 | K20: AMD Infinity Fabric | L20: 750 | M20: Large-model AI/HPC | N20: Confirmed | O20: Dell product specifications | P20: https://www.dell.com/en-us/shop/ipovw/poweredge-xe9680 | Q20: Current product page | R20: Complete accelerator configuration | S20: High | T20: Not applicable | U20: Not applicable | V20: 8 x MI300X | W20: 8 | X20: 8 | Y20: 8 | Z20: 90000 | AA20: 18000 | AB20: =Z20+G20*AA20 -> 234000 | AC20: Low
A21: CMP-007 | B21: DELL-SRV-003 | C21: PowerEdge XE9680 | D21: Intel | E21: Gaudi 3 128GB | F21: OAM | G21: 8 | H21: Fixed 8-accelerator platform | I21: 128 | J21: 1024 | K21: Embedded RoCE | L21: 900 | M21: AI training and inference | N21: Confirmed | O21: Dell product specifications | P21: https://www.dell.com/en-us/shop/ipovw/poweredge-xe9680 | Q21: Current product page | R21: Storage controller constraints apply | S21: Medium | T21: Not applicable | U21: Not applicable | V21: 8 x Gaudi 3 | W21: 8 | X21: 8 | Y21: 8 | Z21: 90000 | AA21: 25000 | AB21: =Z21+G21*AA21 -> 290000 | AC21: Low
A22: CMP-008 | B22: DELL-SRV-004 | C22: PowerEdge XE7745 | D22: NVIDIA | E22: RTX PRO 6000 Blackwell Server Edition 96GB | F22: PCIe DW | G22: 8 | H22: Up to 8 double-wide 600W accelerators | I22: 96 | J22: 768 | K22: PCIe Gen5 | L22: 600 | M22: Enterprise inference / fine-tuning | N22: Confirmed example | O22: Dell specification sheet | P22: https://www.delltechnologies.com/assetlink/doc/tr-tr/poweredge-xe7745-spec-sheet-en-dl1lybn-original.pdf | Q22: 2025/2026 Dell spec | R22: Exact supported counts/configurator validation required | S22: High | T22: 1 x RTX PRO 6000 | U22: 4 x RTX PRO 6000 | V22: 8 x RTX PRO 6000 | W22: 1 | X22: 4 | Y22: 8 | Z22: 55000 | AA22: 16000 | AB22: =Z22+G22*AA22 -> 183000 | AC22: Medium
A23: CMP-009 | B23: DELL-SRV-004 | C23: PowerEdge XE7745 | D23: NVIDIA | E23: H200 NVL 141GB | F23: PCIe DW | G23: 8 | H23: Up to 8 double-wide; exact count validate with Dell | I23: 141 | J23: 1128 | K23: NVLink capable; topology configuration dependent | L23: 600 | M23: Memory-heavy inference / fine-tuning | N23: Dell spec example / matrix confirmation required | O23: Dell specification family + GPU matrix | P23: https://www.delltechnologies.com/assetlink/doc/en-iq/poweredge-server-gpu-matrix-en-dl1h9a2-original.pdf | Q23: Current Dell matrix | R23: Do not mark procurement-ready until exact configurator pairing checked | S23: Medium | T23: 1 x H200 NVL | U23: 4 x H200 NVL | V23: 8 x H200 NVL | W23: 1 | X23: 4 | Y23: 8 | Z23: 55000 | AA23: 40000 | AB23: =Z23+G23*AA23 -> 375000 | AC23: Low
A24: CMP-010 | B24: DELL-SRV-004 | C24: PowerEdge XE7745 | D24: NVIDIA | E24: L4 24GB | F24: PCIe SW | G24: 16 | H24: Up to 16 single-wide 75W accelerators | I24: 24 | J24: 384 | K24: PCIe Gen4/5 host dependent | L24: 72 | M24: High-density efficient inference | N24: Confirmed example | O24: Dell specification sheet | P24: https://www.delltechnologies.com/assetlink/doc/tr-tr/poweredge-xe7745-spec-sheet-en-dl1lybn-original.pdf | Q24: 2025/2026 Dell spec | R24: Exact supported quantities require configured order validation | S24: High | T24: 1 x L4 | U24: 8 x L4 | V24: 16 x L4 | W24: 1 | X24: 8 | Y24: 16 | Z24: 55000 | AA24: 3600 | AB24: =Z24+G24*AA24 -> 112600 | AC24: Medium
A25: CMP-011 | B25: DELL-SRV-006 | C25: PowerEdge XE9780 | D25: NVIDIA | E25: HGX B200 180GB | F25: SXM6 | G25: 8 | H25: Fixed 8-GPU HGX platform | I25: 180 | J25: 1440 | K25: NVLink | L25: 1000 | M25: Frontier model training/inference | N25: Confirmed | O25: Dell product specifications | P25: https://www.dell.com/en-us/shop/ipovw/poweredge-xe9780 | Q25: Current product page | R25: Complete accelerator configuration | S25: High | T25: Not applicable | U25: Not applicable | V25: 8 x B200 | W25: 8 | X25: 8 | Y25: 8 | Z25: 100000 | AA25: 50000 | AB25: =Z25+G25*AA25 -> 500000 | AC25: Low
A26: CMP-012 | B26: DELL-SRV-006 | C26: PowerEdge XE9780 | D26: NVIDIA | E26: HGX B300 270GB | F26: SXM6 | G26: 8 | H26: Fixed 8-GPU HGX NVL8 platform | I26: 270 | J26: 2160 | K26: NVLink | L26: 1100 | M26: Frontier model training/inference | N26: Confirmed | O26: Dell product specifications | P26: https://www.dell.com/en-us/shop/ipovw/poweredge-xe9780 | Q26: Current product page | R26: Complete accelerator configuration | S26: High | T26: Not applicable | U26: Not applicable | V26: 8 x B300 | W26: 8 | X26: 8 | Y26: 8 | Z26: 110000 | AA26: 50000 | AB26: =Z26+G26*AA26 -> 510000 | AC26: Low
A27: CMP-013 | B27: DELL-SRV-007 | C27: PowerEdge XE9785 | D27: AMD | E27: Instinct MI355X 288GB | F27: OAM | G27: 8 | H27: Fixed 8-accelerator platform | I27: 288 | J27: 2304 | K27: AMD Infinity Fabric | L27: 1400 | M27: Frontier model training/inference | N27: Confirmed | O27: Dell product specifications | P27: https://www.dell.com/en-us/shop/ipovw/poweredge-xe9785 | Q27: Current product page | R27: Complete accelerator configuration | S27: High | T27: Not applicable | U27: Not applicable | V27: 8 x MI355X | W27: 8 | X27: 8 | Y27: 8 | Z27: 110000 | AA27: 60000 | AB27: =Z27+G27*AA27 -> 590000 | AC27: Low
A28: CMP-014 | B28: DELL-SRV-007 | C28: PowerEdge XE9785 | D28: NVIDIA | E28: HGX B300 270GB | F28: SXM6 | G28: 8 | H28: Fixed 8-GPU HGX NVL8 platform | I28: 270 | J28: 2160 | K28: NVLink | L28: 1100 | M28: Frontier model training/inference | N28: Confirmed | O28: Dell product specifications | P28: https://www.dell.com/en-us/shop/ipovw/poweredge-xe9785 | Q28: Current product page | R28: Complete accelerator configuration | S28: High | T28: Not applicable | U28: Not applicable | V28: 8 x B300 | W28: 8 | X28: 8 | Y28: 8 | Z28: 110000 | AA28: 50000 | AB28: =Z28+G28*AA28 -> 510000 | AC28: Low
A31: Inference Benchmark Catalog
A32: Benchmark ID | B32: Model ID | C32: Precision | D32: GPU SKU | E32: GPU Qty Tested | F32: Input Tokens | G32: Output Tokens | H32: Concurrency | I32: P95 TTFT ms | J32: ITL ms | K32: Output TPS/System | L32: RPS/System | M32: RPS/GPU | N32: Sequences/GPU | O32: Input TPS/GPU | P32: Benchmark Type | Q32: Confidence | R32: Source URL | S32: Use Rule | T32: Date | U32: Status | V32: Notes
A33: BM-H100-5K500-C50 | B33: MOD-003 | C33: FP8 | D33: H100 SXM5 80GB | E33: 2 | F33: 5000 | G33: 500 | H33: 50 | I33: 834.51 | J33: 59.73 | K33: 814.37 | L33: =K33/G33 -> 1.62874 | M33: =L33/E33 -> 0.81437 | N33: =H33/E33 -> 25 | O33: =L33*F33/E33 -> 4071.85 | P33: Exact Published | Q33: High | R33: https://docs.nvidia.com/nim/benchmarking/llm/1.0.0/performance.html | S33: Use when model/precision and token shape align | T33: 2026-04-01 | U33: Active | V33: NVIDIA NIM Llama 3.3 70B
A34: BM-H100-1K1K-C100 | B34: MOD-003 | C34: FP8 | D34: H100 SXM5 80GB | E34: 2 | F34: 1000 | G34: 1000 | H34: 100 | I34: 334.23 | J34: 34.21 | K34: 2895.49 | L34: =K34/G34 -> 2.89549 | M34: =L34/E34 -> 1.447745 | N34: =H34/E34 -> 50 | O34: =L34*F34/E34 -> 1447.745 | P34: Exact Published | Q34: High | R34: https://docs.nvidia.com/nim/benchmarking/llm/1.0.0/performance.html | S34: Shorter prompt/longer output profile | T34: 2026-04-01 | U34: Active | V34: NVIDIA NIM Llama 3.3 70B
A35: BM-PROXY-L40S | B35: PROXY | C35: INT8 | D35: L40S | E35: 1 | F35: 2000 | G35: 500 | H35: 32 | I35: 1000 | J35: 50 | K35: 500 | L35: =K35/G35 -> 1 | M35: =L35/E35 -> 1 | N35: =H35/E35 -> 32 | O35: =L35*F35/E35 -> 2000 | P35: Nearest Planning Proxy | Q35: Low | R35: https://infohub.delltechnologies.com/en-us/l/design-guide-generative-ai-in-the-enterprise-inferencing/sizing-guidelines-81/ | S35: Replace before procurement | T35: 2026-09-08 | U35: Active | V35: Planning proxy
A36: BM-PROXY-L4 | B36: PROXY | C36: FP16 | D36: L4 | E36: 1 | F36: 1000 | G36: 200 | H36: 16 | I36: 1200 | J36: 75 | K36: 180 | L36: =K36/G36 -> 0.9 | M36: =L36/E36 -> 0.9 | N36: =H36/E36 -> 16 | O36: =L36*F36/E36 -> 900 | P36: Nearest Planning Proxy | Q36: Low | R36: https://docs.nvidia.com/nim/large-language-models/1.4.0/support-matrix.html | S36: Replace before procurement | T36: 2026-09-08 | U36: Active | V36: Planning proxy
A37: BM-PROXY-H200 | B37: PROXY | C37: INT8 | D37: H200 NVL 141GB | E37: 1 | F37: 16000 | G37: 1000 | H37: 32 | I37: 1500 | J37: 40 | K37: 800 | L37: =K37/G37 -> 0.8 | M37: =L37/E37 -> 0.8 | N37: =H37/E37 -> 32 | O37: =L37*F37/E37 -> 12800 | P37: Nearest Planning Proxy | Q37: Low | R37: https://www.nvidia.com/en-us/data-center/h200/ | S37: Replace before procurement | T37: 2026-09-08 | U37: Active | V37: Planning proxy
A38: BM-PROXY-RTX6K | B38: PROXY | C38: INT8 | D38: RTX PRO 6000 Blackwell Server Edition | E38: 1 | F38: 4000 | G38: 500 | H38: 32 | I38: 1000 | J38: 45 | K38: 600 | L38: =K38/G38 -> 1.2 | M38: =L38/E38 -> 1.2 | N38: =H38/E38 -> 32 | O38: =L38*F38/E38 -> 4800 | P38: Nearest Planning Proxy | Q38: Low | R38: https://www.nvidia.com/en-us/data-center/rtx-pro-6000-blackwell-server-edition/ | S38: Replace before procurement | T38: 2026-09-08 | U38: Active | V38: Planning proxy
A39: BM-PROXY-B200 | B39: PROXY | C39: BF16 | D39: B200 SXM6 180GB | E39: 8 | F39: 4096 | G39: 1024 | H39: 256 | I39: 500 | J39: 20 | K39: 10000 | L39: =K39/G39 -> 9.765625 | M39: =L39/E39 -> 1.2207031 | N39: =H39/E39 -> 32 | O39: =L39*F39/E39 -> 5000 | P39: Nearest Planning Proxy | Q39: Low | R39: https://www.dell.com/en-us/shop/ipovw/poweredge-xe9780 | S39: Training completion benchmark required | T39: 2026-09-08 | U39: Active | V39: Planning proxy

Sheet GPU_Server_Selection
A1: Selected Model to GPU and Dell Server Recommendation
A3: Formula ID | B3: Selection Output | C3: Minimum Memory-Fit Option | D3: Moderate Supported Option | E3: Heavy Supported Option | F3: Unit / Type | G3: Selection Logic | H3: Status | I3: Source Key | J3: Notes
A4: SEL-001 | B4: Selected Workload Rule | C4: =Model_Selection!C18 -> WRK-006 | D4: =C4 -> WRK-006 | E4: =C4 -> WRK-006 | F4: ID | G4: Input-to-workload logic | H4: Calculated | I4: Workload Rule ID
A5: SEL-002 | B5: Selected Model ID | C5: =Model_Selection!C20 -> MOD-003 | D5: =C5 -> MOD-003 | E5: =C5 -> MOD-003 | F5: ID | G5: Candidate or override | H5: Candidate | I5: Model ID | J5: Evaluation evidence required
A6: SEL-003 | B6: Selected Model | C6: =Model_Selection!C21 -> Llama 3.3 70B Instruct | D6: =C6 -> Llama 3.3 70B Instruct | E6: =C6 -> Llama 3.3 70B Instruct | F6: model | G6: Model catalog lookup | H6: Candidate Model | I6: Model ID | J6: Not final approved
A7: SEL-004 | B7: Selected Mapping ID | C7: =IFERROR(INDEX(Model_Mapping_Catalog!$A$31:$A$53,MATCH(C5&"|"&C4,Model_Mapping_Catalog!$AC$31:$AC$53,0)),"Mapping Required") -> MGPU-021 | D7: =C7 -> MGPU-021 | E7: =C7 -> MGPU-021 | F7: ID | G7: Model ID + Workload Rule ID | H7: Calculated | I7: Mapping ID
A8: SEL-005 | B8: GPU ID | C8: =IFERROR(INDEX(Model_Mapping_Catalog!$K$31:$K$53,MATCH(C7,Model_Mapping_Catalog!$A$31:$A$53,0)),"Data Required") -> GPU-NV-004 | D8: =C8 -> GPU-NV-004 | E8: =C8 -> GPU-NV-004 | F8: ID | G8: Mapping lookup | H8: Calculated | I8: GPU ID
A9: SEL-006 | B9: GPU SKU | C9: =IFERROR(INDEX(Model_Mapping_Catalog!$M$31:$M$53,MATCH(C7,Model_Mapping_Catalog!$A$31:$A$53,0)),"Data Required") -> H100 SXM5 80GB | D9: =C9 -> H100 SXM5 80GB | E9: =C9 -> H100 SXM5 80GB | F9: GPU | G9: Mapping lookup | H9: Candidate | I9: GPU ID
A10: SEL-007 | B10: GPU VRAM / GPU | C10: =IFERROR(INDEX(Model_Mapping_Catalog!$N$31:$N$53,MATCH(C7,Model_Mapping_Catalog!$A$31:$A$53,0)),"Data Required") -> 80 | D10: =C10 -> 80 | E10: =C10 -> 80 | F10: GB | G10: Mapping lookup | H10: Source-Backed | I10: GPU ID
A11: SEL-008 | B11: Precision | C11: =IFERROR(INDEX(Model_Mapping_Catalog!$F$31:$F$53,MATCH(C7,Model_Mapping_Catalog!$A$31:$A$53,0)),"Data Required") -> FP8 | D11: =C11 -> FP8 | E11: =C11 -> FP8 | F11: precision | G11: Mapping lookup | H11: Calculated | I11: Mapping ID
A12: MEM-001 | B12: Model Weight Memory | C12: =IFERROR(INDEX(Model_Mapping_Catalog!$H$31:$H$53,MATCH(C7,Model_Mapping_Catalog!$A$31:$A$53,0)),"Data Required") -> 70 | D12: =C12 -> 70 | E12: =C12 -> 70 | F12: GB | G12: Parameters x bytes/parameter | H12: Calculated | I12: Mapping ID
A13: MEM-002 | B13: Runtime Workspace | C13: =IF(C12="Data Required","Data Required",MAX(8,C12*0.1)) -> 8 | D13: =C13 -> 8 | E13: =C13 -> 8 | F13: GB | G13: Planning: max(8 GB, 10% weights) | H13: Planning | I13: Runtime measurement | J13: Replace with measured runtime
A14: MEM-003 | B14: KV Cache Memory | C14: =Model_Selection!C12*Input!C13*0.00004 -> 380.24 | D14: =C14 -> 380.24 | E14: =C14 -> 380.24 | F14: GB | G14: Context x active sequences planning proxy | H14: Planning | I14: KV measurement | J14: Architecture-specific replacement required
A15: MEM-004 | B15: Total Required VRAM | C15: =SUM(C12:C14) -> 458.24 | D15: =C15 -> 458.24 | E15: =C15 -> 458.24 | F15: GB | G15: Weights + runtime + KV cache | H15: Calculated | I15: Memory
A16: CAP-001 | B16: Memory GPU Minimum | C16: =ROUNDUP(C15/(C10*0.9),0) -> 7 | D16: =C16 -> 7 | E16: =C16 -> 7 | F16: GPUs | G16: Required VRAM / 90% usable VRAM | H16: Calculated | I16: Memory
A17: BM-001 | B17: Benchmark ID | C17: =IFERROR(INDEX(Model_Mapping_Catalog!$AE$31:$AE$53,MATCH(C7,Model_Mapping_Catalog!$A$31:$A$53,0)),"Benchmark Required") -> BM-H100-5K500-C50 | D17: =C17 -> BM-H100-5K500-C50 | E17: =C17 -> BM-H100-5K500-C50 | F17: ID | G17: Mapping benchmark link | H17: Calculated | I17: Benchmark ID
A18: BM-002 | B18: Benchmark Type | C18: =IFERROR(INDEX(Hardware_Mapping_Catalog!$P$33:$P$39,MATCH(C17,Hardware_Mapping_Catalog!$A$33:$A$39,0)),"Benchmark Required") -> Exact Published | D18: =C18 -> Exact Published | E18: =C18 -> Exact Published | F18: type | G18: Benchmark lookup | H18: Calculated | I18: Benchmark ID
A19: BM-003 | B19: Benchmark Confidence | C19: =IFERROR(INDEX(Hardware_Mapping_Catalog!$Q$33:$Q$39,MATCH(C17,Hardware_Mapping_Catalog!$A$33:$A$39,0)),"Low") -> High | D19: =C19 -> High | E19: =C19 -> High | F19: confidence | G19: Benchmark lookup | H19: Calculated | I19: Benchmark ID
A20: BM-004 | B20: Benchmark P95 TTFT | C20: =IFERROR(INDEX(Hardware_Mapping_Catalog!$I$33:$I$39,MATCH(C17,Hardware_Mapping_Catalog!$A$33:$A$39,0)),"Data Required") -> 834.51 | D20: =C20 -> 834.51 | E20: =C20 -> 834.51 | F20: ms | G20: Benchmark lookup | H20: Calculated | I20: Benchmark ID
A21: BM-005 | B21: Benchmark ITL | C21: =IFERROR(INDEX(Hardware_Mapping_Catalog!$J$33:$J$39,MATCH(C17,Hardware_Mapping_Catalog!$A$33:$A$39,0)),"Data Required") -> 59.73 | D21: =C21 -> 59.73 | E21: =C21 -> 59.73 | F21: ms/token | G21: Benchmark lookup | H21: Calculated | I21: Benchmark ID
A22: BM-006 | B22: Benchmark RPS / GPU | C22: =IFERROR(INDEX(Hardware_Mapping_Catalog!$M$33:$M$39,MATCH(C17,Hardware_Mapping_Catalog!$A$33:$A$39,0)),"Data Required") -> 0.81437 | D22: =C22 -> 0.81437 | E22: =C22 -> 0.81437 | F22: requests/sec/GPU | G22: Benchmark lookup | H22: Calculated | I22: Benchmark ID
A23: BM-007 | B23: Benchmark Sequences / GPU | C23: =IFERROR(INDEX(Hardware_Mapping_Catalog!$N$33:$N$39,MATCH(C17,Hardware_Mapping_Catalog!$A$33:$A$39,0)),"Data Required") -> 25 | D23: =C23 -> 25 | E23: =C23 -> 25 | F23: sequences/GPU | G23: Benchmark lookup | H23: Calculated | I23: Benchmark ID
